<?xml version='1.0'?>
<sdf version="1.4">
<model name="double_inverted_pendulum">
  <pose>0 0 0 0 0 0</pose>
  <static>false</static>


  <link name = "base">
  <pose>0 0 0 0 0 0</pose>
  <inertial>
  <mass>0.2</mass>
  <inertia> <!-- interias are tricky to compute -->
    <!-- http://answers.gazebosim.org/question/4372/the-inertia-matrix-explained/ -->
    <ixx>0.083</ixx>       <!-- for a box: ixx = 0.083 * mass * (y*y + z*z) -->
    <ixy>0.0</ixy>         <!-- for a box: ixy = 0 -->
    <ixz>0.0</ixz>         <!-- for a box: ixz = 0 -->
    <iyy>0.083</iyy>       <!-- for a box: iyy = 0.083 * mass * (x*x + z*z) -->
    <iyz>0.0</iyz>         <!-- for a box: iyz = 0 -->
    <izz>0.083</izz>       <!-- for a box: izz = 0.083 * mass * (x*x + y*y) -->
    </inertia>
  </inertial>
  <collision name="collision_base">
    <geometry>
      <box>
        <size>1 1 1</size>
      </box>
    </geometry>
  </collision>
  <visual name="visual_base">
    <geometry>
      <box>
        <size>1 1 1</size>
      </box>
    </geometry>
  </visual>
</link>





    <link name="link1">
    <pose>1 0 0 0 0 0</pose>
      <inertial>
        <mass>1.0</mass>
        <inertia> <!-- interias are tricky to compute -->
          <!-- http://answers.gazebosim.org/question/4372/the-inertia-matrix-explained/ -->
          <ixx>0.083</ixx>       <!-- for a box: ixx = 0.083 * mass * (y*y + z*z) -->
          <ixy>0.0</ixy>         <!-- for a box: ixy = 0 -->
          <ixz>0.0</ixz>         <!-- for a box: ixz = 0 -->
          <iyy>0.083</iyy>       <!-- for a box: iyy = 0.083 * mass * (x*x + z*z) -->
          <iyz>0.0</iyz>         <!-- for a box: iyz = 0 -->
          <izz>0.083</izz>       <!-- for a box: izz = 0.083 * mass * (x*x + y*y) -->
        </inertia>
      </inertial>
      <collision name="collision1">
        <geometry>
          <box>
            <size>1 1 5</size>
          </box>
        </geometry>
      </collision>
      <visual name="visual1">
        <geometry>
          <box>
            <size>1 1 5</size>
          </box>
        </geometry>
      </visual>
    </link>


    <link name="link2">
    <pose>2 0 4.5 0 0 0</pose>
      <inertial>
        <mass>1.0</mass>
        <inertia> <!-- interias are tricky to compute -->
          <!-- http://answers.gazebosim.org/question/4372/the-inertia-matrix-explained/ -->
          <ixx>0.083</ixx>       <!-- for a box: ixx = 0.083 * mass * (y*y + z*z) -->
          <ixy>0.0</ixy>         <!-- for a box: ixy = 0 -->
          <ixz>0.0</ixz>         <!-- for a box: ixz = 0 -->
          <iyy>0.083</iyy>       <!-- for a box: iyy = 0.083 * mass * (x*x + z*z) -->
          <iyz>0.0</iyz>         <!-- for a box: iyz = 0 -->
          <izz>0.083</izz>       <!-- for a box: izz = 0.083 * mass * (x*x + y*y) -->
        </inertia>
      </inertial>
      <collision name="collision2">
        <geometry>
          <box>
            <size>1 1 5</size>
          </box>
        </geometry>
      </collision>
      <visual name="visual2">
        <geometry>
          <box>
            <size>1 1 5</size>
          </box>
        </geometry>
      </visual>
    </link>


    <joint type="revolute" name="base_link1_rev">
      <pose>1 0 0 0 0 0</pose>
      <child>link1</child>
      <parent>base</parent>
      <axis>
        <xyz>0 1 0</xyz>
      </axis>
    </joint>

    <joint type="revolute" name="base_link1_rev">
      <pose>2 0 4.5 0 0</pose>
      <child>link1</child>
      <parent>base</parent>
      <axis>
        <xyz>0 1 0</xyz>
      </axis>
    </joint>


  </model>
</sdf>
